Traceback (most recent call last):
  File "C:\Python\Python311\Lib\site-packages\jupyter_cache\executors\utils.py", line 58, in single_nb_execution
    executenb(
  File "C:\Python\Python311\Lib\site-packages\nbclient\client.py", line 1204, in execute
    return NotebookClient(nb=nb, resources=resources, km=km, **kwargs).execute()
           ^^^^^^^^^^^^^^^^^^^^^^^^^^^^^^^^^^^^^^^^^^^^^^^^^^^^^^^^^^^^^^^^^^^^^
  File "C:\Python\Python311\Lib\site-packages\nbclient\util.py", line 84, in wrapped
    return just_run(coro(*args, **kwargs))
           ^^^^^^^^^^^^^^^^^^^^^^^^^^^^^^^
  File "C:\Python\Python311\Lib\site-packages\nbclient\util.py", line 62, in just_run
    return loop.run_until_complete(coro)
           ^^^^^^^^^^^^^^^^^^^^^^^^^^^^^
  File "C:\Python\Python311\Lib\asyncio\base_events.py", line 650, in run_until_complete
    return future.result()
           ^^^^^^^^^^^^^^^
  File "C:\Python\Python311\Lib\contextlib.py", line 222, in __aexit__
    await self.gen.athrow(typ, value, traceback)
  File "C:\Python\Python311\Lib\site-packages\nbclient\client.py", line 608, in async_setup_kernel
    yield
  File "C:\Python\Python311\Lib\site-packages\nbclient\client.py", line 663, in async_execute
    await self.async_execute_cell(
  File "C:\Python\Python311\Lib\site-packages\nbclient\client.py", line 965, in async_execute_cell
    await self._check_raise_for_error(cell, cell_index, exec_reply)
  File "C:\Python\Python311\Lib\site-packages\nbclient\client.py", line 862, in _check_raise_for_error
    raise CellExecutionError.from_cell_and_msg(cell, exec_reply_content)
nbclient.exceptions.CellExecutionError: An error occurred while executing the following cell:
------------------
for number in range(10):
    if number == 5:
        # comment
        raise Exception('This is the output of exception.')

    elif number == 3:
        #number = number + 1
        print( f'This number is {number}' )

    else:
        #number = number + 2
        print('Different number')

    print('Number is ' + str(number))

print('Out of loop')
------------------

[1;31m---------------------------------------------------------------------------[0m
[1;31mException[0m                                 Traceback (most recent call last)
Cell [1;32mIn[80], line 4[0m
[0;32m      1[0m [38;5;28;01mfor[39;00m number [38;5;129;01min[39;00m [38;5;28mrange[39m([38;5;241m10[39m):
[0;32m      2[0m     [38;5;28;01mif[39;00m number [38;5;241m==[39m [38;5;241m5[39m:
[0;32m      3[0m         [38;5;66;03m# comment[39;00m
[1;32m----> 4[0m         [38;5;28;01mraise[39;00m [38;5;167;01mException[39;00m([38;5;124m'[39m[38;5;124mThis is the output of exception.[39m[38;5;124m'[39m)
[0;32m      6[0m     [38;5;28;01melif[39;00m number [38;5;241m==[39m [38;5;241m3[39m:
[0;32m      7[0m         [38;5;66;03m#number = number + 1[39;00m
[0;32m      8[0m         [38;5;28mprint[39m( [38;5;124mf[39m[38;5;124m'[39m[38;5;124mThis number is [39m[38;5;132;01m{[39;00mnumber[38;5;132;01m}[39;00m[38;5;124m'[39m )

[1;31mException[0m: This is the output of exception.
Exception: This is the output of exception.

