Traceback (most recent call last):
  File "C:\Python\Python311\Lib\site-packages\jupyter_cache\executors\utils.py", line 58, in single_nb_execution
    executenb(
  File "C:\Python\Python311\Lib\site-packages\nbclient\client.py", line 1204, in execute
    return NotebookClient(nb=nb, resources=resources, km=km, **kwargs).execute()
           ^^^^^^^^^^^^^^^^^^^^^^^^^^^^^^^^^^^^^^^^^^^^^^^^^^^^^^^^^^^^^^^^^^^^^
  File "C:\Python\Python311\Lib\site-packages\nbclient\util.py", line 84, in wrapped
    return just_run(coro(*args, **kwargs))
           ^^^^^^^^^^^^^^^^^^^^^^^^^^^^^^^
  File "C:\Python\Python311\Lib\site-packages\nbclient\util.py", line 62, in just_run
    return loop.run_until_complete(coro)
           ^^^^^^^^^^^^^^^^^^^^^^^^^^^^^
  File "C:\Python\Python311\Lib\asyncio\base_events.py", line 650, in run_until_complete
    return future.result()
           ^^^^^^^^^^^^^^^
  File "C:\Python\Python311\Lib\contextlib.py", line 222, in __aexit__
    await self.gen.athrow(typ, value, traceback)
  File "C:\Python\Python311\Lib\site-packages\nbclient\client.py", line 608, in async_setup_kernel
    yield
  File "C:\Python\Python311\Lib\site-packages\nbclient\client.py", line 663, in async_execute
    await self.async_execute_cell(
  File "C:\Python\Python311\Lib\site-packages\nbclient\client.py", line 965, in async_execute_cell
    await self._check_raise_for_error(cell, cell_index, exec_reply)
  File "C:\Python\Python311\Lib\site-packages\nbclient\client.py", line 862, in _check_raise_for_error
    raise CellExecutionError.from_cell_and_msg(cell, exec_reply_content)
nbclient.exceptions.CellExecutionError: An error occurred while executing the following cell:
------------------
with open( r'../_data/ID_Routes_firms.csv' , encoding="utf8", errors='ignore') as csvfile:
    readCSV = csv.reader(csvfile, delimiter=',')
    town = []
    
    for row in readCSV:
        gem = row[6]
        town.append(gem)
        print(', '.join(row))
------------------

[1;31m---------------------------------------------------------------------------[0m
[1;31mFileNotFoundError[0m                         Traceback (most recent call last)
Cell [1;32mIn[14], line 1[0m
[1;32m----> 1[0m [38;5;28;01mwith[39;00m [38;5;28;43mopen[39;49m[43m([49m[43m [49m[38;5;124;43mr[39;49m[38;5;124;43m'[39;49m[38;5;124;43m../_data/ID_Routes_firms.csv[39;49m[38;5;124;43m'[39;49m[43m [49m[43m,[49m[43m [49m[43mencoding[49m[38;5;241;43m=[39;49m[38;5;124;43m"[39;49m[38;5;124;43mutf8[39;49m[38;5;124;43m"[39;49m[43m,[49m[43m [49m[43merrors[49m[38;5;241;43m=[39;49m[38;5;124;43m'[39;49m[38;5;124;43mignore[39;49m[38;5;124;43m'[39;49m[43m)[49m [38;5;28;01mas[39;00m csvfile:
[0;32m      2[0m     readCSV [38;5;241m=[39m csv[38;5;241m.[39mreader(csvfile, delimiter[38;5;241m=[39m[38;5;124m'[39m[38;5;124m,[39m[38;5;124m'[39m)
[0;32m      3[0m     town [38;5;241m=[39m []

File [1;32mC:\Python\Python311\Lib\site-packages\IPython\core\interactiveshell.py:284[0m, in [0;36m_modified_open[1;34m(file, *args, **kwargs)[0m
[0;32m    277[0m [38;5;28;01mif[39;00m file [38;5;129;01min[39;00m {[38;5;241m0[39m, [38;5;241m1[39m, [38;5;241m2[39m}:
[0;32m    278[0m     [38;5;28;01mraise[39;00m [38;5;167;01mValueError[39;00m(
[0;32m    279[0m         [38;5;124mf[39m[38;5;124m"[39m[38;5;124mIPython won[39m[38;5;124m'[39m[38;5;124mt let you open fd=[39m[38;5;132;01m{[39;00mfile[38;5;132;01m}[39;00m[38;5;124m by default [39m[38;5;124m"[39m
[0;32m    280[0m         [38;5;124m"[39m[38;5;124mas it is likely to crash IPython. If you know what you are doing, [39m[38;5;124m"[39m
[0;32m    281[0m         [38;5;124m"[39m[38;5;124myou can use builtins[39m[38;5;124m'[39m[38;5;124m open.[39m[38;5;124m"[39m
[0;32m    282[0m     )
[1;32m--> 284[0m [38;5;28;01mreturn[39;00m [43mio_open[49m[43m([49m[43mfile[49m[43m,[49m[43m [49m[38;5;241;43m*[39;49m[43margs[49m[43m,[49m[43m [49m[38;5;241;43m*[39;49m[38;5;241;43m*[39;49m[43mkwargs[49m[43m)[49m

[1;31mFileNotFoundError[0m: [Errno 2] No such file or directory: '../_data/ID_Routes_firms.csv'
FileNotFoundError: [Errno 2] No such file or directory: '../_data/ID_Routes_firms.csv'

