Traceback (most recent call last):
  File "C:\Python\Python311\Lib\site-packages\jupyter_cache\executors\utils.py", line 58, in single_nb_execution
    executenb(
  File "C:\Python\Python311\Lib\site-packages\nbclient\client.py", line 1204, in execute
    return NotebookClient(nb=nb, resources=resources, km=km, **kwargs).execute()
           ^^^^^^^^^^^^^^^^^^^^^^^^^^^^^^^^^^^^^^^^^^^^^^^^^^^^^^^^^^^^^^^^^^^^^
  File "C:\Python\Python311\Lib\site-packages\nbclient\util.py", line 84, in wrapped
    return just_run(coro(*args, **kwargs))
           ^^^^^^^^^^^^^^^^^^^^^^^^^^^^^^^
  File "C:\Python\Python311\Lib\site-packages\nbclient\util.py", line 62, in just_run
    return loop.run_until_complete(coro)
           ^^^^^^^^^^^^^^^^^^^^^^^^^^^^^
  File "C:\Python\Python311\Lib\asyncio\base_events.py", line 650, in run_until_complete
    return future.result()
           ^^^^^^^^^^^^^^^
  File "C:\Python\Python311\Lib\contextlib.py", line 222, in __aexit__
    await self.gen.athrow(typ, value, traceback)
  File "C:\Python\Python311\Lib\site-packages\nbclient\client.py", line 608, in async_setup_kernel
    yield
  File "C:\Python\Python311\Lib\site-packages\nbclient\client.py", line 663, in async_execute
    await self.async_execute_cell(
  File "C:\Python\Python311\Lib\site-packages\nbclient\client.py", line 965, in async_execute_cell
    await self._check_raise_for_error(cell, cell_index, exec_reply)
  File "C:\Python\Python311\Lib\site-packages\nbclient\client.py", line 862, in _check_raise_for_error
    raise CellExecutionError.from_cell_and_msg(cell, exec_reply_content)
nbclient.exceptions.CellExecutionError: An error occurred while executing the following cell:
------------------
tuple1[0] = 15
------------------

[1;31m---------------------------------------------------------------------------[0m
[1;31mTypeError[0m                                 Traceback (most recent call last)
Cell [1;32mIn[52], line 1[0m
[1;32m----> 1[0m [43mtuple1[49m[43m[[49m[38;5;241;43m0[39;49m[43m][49m [38;5;241m=[39m [38;5;241m15[39m

[1;31mTypeError[0m: 'tuple' object does not support item assignment
TypeError: 'tuple' object does not support item assignment

